Workbook

Sheet Libro de Ventas
A2: Razon Social: | B2: KING DRIVER, C.A.
A3: R.I.F: | B3: J507757188
A4: Direccion | B4: AV. JOSE ANTONIO PAEZ EDIF RESIDENCIAS 2000 RESIDENCIAS CECILIA PISO PH APT 43 URB EL PARAISO CARACAS DISTRITO CAPITAL ZONA POSTAL 1020.
A5: Libro de Ventas
A6: Periodo: | B6: 202610
A7: Fecha | B7: 46326
O10: Ventas Internas Contribuyentes / No contribuyentes
A11: Fecha de Factura | B11: Nombre y Apellido o Razón Social | C11: R.I.F. | D11: Número de Factura | E11: Num. Control de Factura | F11: Nro de Máquina | G11: Reporte Z | H11: Nro Serie Factura | I11: Nro. Última Factura | J11: Número Nota Débito | K11: Número de Nota Crédito | L11: Número de Factura Afectada | M11: Total Ventas Incluyendo el IVA | N11: Ventas Exentas | O11: Base Imponible | P11: % Alícuota | Q11: Débito Fiscal
A12: =Data!A2 -> 46296 | B12: =Data!B2 -> CARLOS JOSE RODRIGUEZ COLMENARES | C12: =Data!C2 -> V149899452 | D12: =Data!D2 -> 1 | E12: =Data!E2 -> 1 | F12: =Data!F2 -> 0 | G12: =Data!G2 -> 0 | H12: =Data!H2 -> 0 | ... Q12: =Data!Q2 -> 2400
A13: =Data!#REF! -> #REF! | B13: =Data!#REF! -> #REF! | C13: =Data!#REF! -> #REF! | D13: =Data!#REF! -> #REF! | E13: =Data!#REF! -> #REF! | F13: =Data!#REF! -> #REF! | G13: =Data!#REF! -> #REF! | H13: =Data!#REF! -> #REF! | ... Q13: =Data!#REF! -> #REF!
A14: =Data!#REF! -> #REF! | B14: =Data!#REF! -> #REF! | C14: =Data!#REF! -> #REF! | D14: =Data!#REF! -> #REF! | E14: =Data!#REF! -> #REF! | F14: =Data!#REF! -> #REF! | G14: =Data!#REF! -> #REF! | H14: =Data!#REF! -> #REF! | ... Q14: =Data!#REF! -> #REF!
A15: =Data!#REF! -> #REF! | B15: =Data!#REF! -> #REF! | C15: =Data!#REF! -> #REF! | D15: =Data!#REF! -> #REF! | E15: =Data!#REF! -> #REF! | F15: =Data!#REF! -> #REF! | G15: =Data!#REF! -> #REF! | H15: =Data!#REF! -> #REF! | ... Q15: =Data!#REF! -> #REF!
A16: =Data!#REF! -> #REF! | B16: =Data!#REF! -> #REF! | C16: =Data!#REF! -> #REF! | D16: =Data!#REF! -> #REF! | E16: =Data!#REF! -> #REF! | F16: =Data!#REF! -> #REF! | G16: =Data!#REF! -> #REF! | H16: =Data!#REF! -> #REF! | ... Q16: =Data!#REF! -> #REF!
A17: =Data!#REF! -> #REF! | B17: =Data!#REF! -> #REF! | C17: =Data!#REF! -> #REF! | D17: =Data!#REF! -> #REF! | E17: =Data!#REF! -> #REF! | F17: =Data!#REF! -> #REF! | G17: =Data!#REF! -> #REF! | H17: =Data!#REF! -> #REF! | ... Q17: =Data!#REF! -> #REF!
A18: =Data!#REF! -> #REF! | B18: =Data!#REF! -> #REF! | C18: =Data!#REF! -> #REF! | D18: =Data!#REF! -> #REF! | E18: =Data!#REF! -> #REF! | F18: =Data!#REF! -> #REF! | G18: =Data!#REF! -> #REF! | H18: =Data!#REF! -> #REF! | ... Q18: =Data!#REF! -> #REF!
A19: =Data!#REF! -> #REF! | B19: =Data!#REF! -> #REF! | C19: =Data!#REF! -> #REF! | D19: =Data!#REF! -> #REF! | E19: =Data!#REF! -> #REF! | F19: =Data!#REF! -> #REF! | G19: =Data!#REF! -> #REF! | H19: =Data!#REF! -> #REF! | ... Q19: =Data!#REF! -> #REF!
A20: =Data!#REF! -> #REF! | B20: =Data!#REF! -> #REF! | C20: =Data!#REF! -> #REF! | D20: =Data!#REF! -> #REF! | E20: =Data!#REF! -> #REF! | F20: =Data!#REF! -> #REF! | G20: =Data!#REF! -> #REF! | H20: =Data!#REF! -> #REF! | ... Q20: =Data!#REF! -> #REF!
A21: =Data!#REF! -> #REF! | B21: =Data!#REF! -> #REF! | C21: =Data!#REF! -> #REF! | D21: =Data!#REF! -> #REF! | E21: =Data!#REF! -> #REF! | F21: =Data!#REF! -> #REF! | G21: =Data!#REF! -> #REF! | H21: =Data!#REF! -> #REF! | ... Q21: =Data!#REF! -> #REF!
A22: =Data!#REF! -> #REF! | B22: =Data!#REF! -> #REF! | C22: =Data!#REF! -> #REF! | D22: =Data!#REF! -> #REF! | E22: =Data!#REF! -> #REF! | F22: =Data!#REF! -> #REF! | G22: =Data!#REF! -> #REF! | H22: =Data!#REF! -> #REF! | ... Q22: =Data!#REF! -> #REF!
A23: =Data!#REF! -> #REF! | B23: =Data!#REF! -> #REF! | C23: =Data!#REF! -> #REF! | D23: =Data!#REF! -> #REF! | E23: =Data!#REF! -> #REF! | F23: =Data!#REF! -> #REF! | G23: =Data!#REF! -> #REF! | H23: =Data!#REF! -> #REF! | ... Q23: =Data!#REF! -> #REF!
A24: =Data!#REF! -> #REF! | B24: =Data!#REF! -> #REF! | C24: =Data!#REF! -> #REF! | D24: =Data!#REF! -> #REF! | E24: =Data!#REF! -> #REF! | F24: =Data!#REF! -> #REF! | G24: =Data!#REF! -> #REF! | H24: =Data!#REF! -> #REF! | ... Q24: =Data!#REF! -> #REF!
... A26: =Data!#REF! -> #REF! | B26: =Data!#REF! -> #REF! | C26: =Data!#REF! -> #REF! | D26: =Data!#REF! -> #REF! | E26: =Data!#REF! -> #REF! | F26: =Data!#REF! -> #REF! | G26: =Data!#REF! -> #REF! | H26: =Data!#REF! -> #REF! | ... Q26: =Data!#REF! -> #REF!
A27: =Data!A3 -> 46297 | B27: =Data!B3 -> CARLOS JOSE RODRIGUEZ COLMENARES | C27: =Data!C3 -> V149899452 | D27: =Data!D3 -> 2 | E27: =Data!E3 -> 2 | F27: =Data!F3 -> 0 | G27: =Data!G3 -> 0 | H27: =Data!H3 -> 0 | ... Q27: =Data!Q3 -> 2400
L28: TOTALES: | M28: =SUM(M12:M26) -> #REF! | N28: =SUM(N12:N26) -> #REF! | O28: =SUM(O12:O26) -> #REF! | Q28: =SUM(Q12:Q26) -> #REF!
M32: Resumen Débitos Fiscales | Q32: -
M33: DEBITOS FISCALES | Q33: BASE IMPONIBLE
M34: Ventas internas no gravadas | Q34: =O28 -> #REF!
M35: Ventas internas gravadas por alícuota general | Q35: =N28 -> #REF!
M36: Ajustes a los débitos fiscales de períodos anteriores | Q36: 0
M37: Total ventas y débitos fiscal para efectos de determinación | Q37: =Q34+Q35+Q36 -> #REF!
M38: Total Débitos Fiscales. | Q38: =Q28 -> #REF!
M39: Resumen Créditos Fiscales | Q39: -
M40: CREDITOS FISCALES | Q40: BASE IMPONIBLE
M41: Compras no gravadas y/o sin derecho a crédito fiscal | Q41: 0
M42: Importación gravadas por alícuota general | Q42: 0
M43: Compras internas gravadas por alícuota general | Q43: 0
M44: Compras internas gravadas por alícuota reducida | Q44: 0
M45: Total compras y créditos fiscales del periodo | Q45: 0
M46: Ajustes a los créditos fiscales de períodos anteriores | Q46: 0
M47: Total Créditos Fiscales | Q47: 0
...

Sheet Data
A1: Fecha de Factura | B1: Nombre y Apellido o Razón Social | C1: R.I.F. | D1: Número de Factura | E1: Num. Control de Factura | F1: Nro de Máquina | G1: Reporte Z | H1: Nro Serie Factura | I1: Nro. Última Factura | J1: Número Nota Débito | K1: Número de Nota Crédito | L1: Número de Factura Afectada | M1: Total Ventas Incluyendo el IVA | N1: Ventas Exentas | O1: Base Imponible | P1: % Alícuota | Q1: Débito Fiscal
A2: 46296 | B2: CARLOS JOSE RODRIGUEZ COLMENARES | C2: V149899452 | D2: 1 | E2: 1 | F2: 0 | G2: 0 | H2: 0 | I2: 0 | J2: 0 | K2: 0 | L2: 0 | M2: =N2+O2+Q2 -> 42400 | N2: 25000 | O2: 15000 | P2: 16 | Q2: =O2*(P2/100) -> 2400
A3: 46297 | B3: CARLOS JOSE RODRIGUEZ COLMENARES | C3: V149899452 | D3: 2 | E3: 2 | F3: 0 | G3: 0 | H3: 0 | I3: 0 | J3: 0 | K3: 0 | L3: 0 | M3: =N3+O3+Q3 -> 42400 | N3: 25000 | O3: 15000 | P3: 16 | Q3: =O3*(P3/100) -> 2400
A4: 46298 | B4: CARLOS JOSE RODRIGUEZ COLMENARES | C4: V149899452 | D4: 3 | E4: 3 | F4: 0 | G4: 0 | H4: 0 | I4: 0 | J4: 0 | K4: 0 | L4: 0 | M4: =N4+O4+Q4 -> 42400 | N4: 25000 | O4: 15000 | P4: 16 | Q4: =O4*(P4/100) -> 2400
