Workbook

Sheet Libro de Compras
A2: Razon Social: | B2: KING DRIVER, C.A.
A3: R.I.F: | B3: J507757188
A4: Direccion | B4: AV. JOSE ANTONIO PAEZ EDIF RESIDENCIAS 2000 RESIDENCIAS CECILIA PISO PH APT 43 URB EL PARAISO CARACAS DISTRITO CAPITAL ZONA POSTAL 1020.
A5: Libro de Compra
A6: Periodo: | B6: 202604
A7: Fecha | B7: 31/04/2026
I18: Compras Nacionales (16%) | K18: Compras Importacion (16%) | M18: Alicuota Reducida (8%) | O18: Retencion 75%
A19: Fecha de Operación | B19: Tipo de Documento | C19: Número de Documento | D19: Número de Control | E19: Nombre o Razón Social | F19: R.I.F. | G19: Total Compras | H19: Compras Exentas | I19: Base Imponible | J19: Credito Fiscales | K19: Base Imponible | L19: Credito Fiscales | M19: Base Imponible | N19: Credito Fiscales | O19: Nº Documento | P19: 0.75
A20: =Data!A2 -> 46249 | B20: =Data!B2 -> 1 | C20: =Data!C2 -> 5 | D20: =Data!D2 -> 5 | E20: =Data!E2 -> Carlos Jose Rodrguez Colmenares | F20: =Data!F2 -> V149899452 | G20: =Data!G2 -> 19280 | H20: =Data!H2 -> 10000 | I20: =Data!I2 -> 8000 | J20: =I20*16/100 -> 1280 | K20: 0 | L20: =K20*16/100 -> 0 | M20: 0 | N20: =M20*8/100 -> 0 | P20: =(J20*75)+(L20*75/100)+(N20*75/100) -> 96000
G21: =H21+I21+J21+K21+L21+M21+N21 -> 0 | H21: 0 | J21: =I21*16/100 -> 0 | L21: =K21*16/100 -> 0 | N21: =M21*8/100 -> 0 | P21: =(J21*75)+(L21*75/100)+(N21*75/100) -> 0
G22: =H22+I22+J22+K22+L22+M22+N22 -> 0 | H22: 0 | J22: =I22*16/100 -> 0 | L22: =K22*16/100 -> 0 | N22: =M22*8/100 -> 0 | P22: =(J22*75)+(L22*75/100)+(N22*75/100) -> 0
G23: =H23+I23+J23+K23+L23+M23+N23 -> 0 | H23: 0 | J23: =I23*16/100 -> 0 | L23: =K23*16/100 -> 0 | N23: =M23*8/100 -> 0 | P23: =(J23*75)+(L23*75/100)+(N23*75/100) -> 0
G24: =H24+I24+J24+K24+L24+M24+N24 -> 0 | H24: 0 | J24: =I24*16/100 -> 0 | L24: =K24*16/100 -> 0 | N24: =M24*8/100 -> 0 | P24: =(J24*75)+(L24*75/100)+(N24*75/100) -> 0
G25: =H25+I25+J25+K25+L25+M25+N25 -> 0 | H25: 0 | J25: =I25*16/100 -> 0 | L25: =K25*16/100 -> 0 | N25: =M25*8/100 -> 0 | P25: =(J25*75)+(L25*75/100)+(N25*75/100) -> 0
G26: =H26+I26+J26+K26+L26+M26+N26 -> 0 | H26: 0 | J26: =I26*16/100 -> 0 | L26: =K26*16/100 -> 0 | N26: =M26*8/100 -> 0 | P26: =(J26*75)+(L26*75/100)+(N26*75/100) -> 0
G27: =H27+I27+J27+K27+L27+M27+N27 -> 0 | H27: 0 | J27: =I27*16/100 -> 0 | L27: =K27*16/100 -> 0 | N27: =M27*8/100 -> 0 | P27: =(J27*75)+(L27*75/100)+(N27*75/100) -> 0
G28: =H28+I28+J28+K28+L28+M28+N28 -> 0 | H28: 0 | J28: =I28*16/100 -> 0 | L28: =K28*16/100 -> 0 | N28: =M28*8/100 -> 0 | P28: =(J28*75)+(L28*75/100)+(N28*75/100) -> 0
G29: =H29+I29+J29+K29+L29+M29+N29 -> 0 | H29: 0 | J29: =I29*16/100 -> 0 | L29: =K29*16/100 -> 0 | N29: =M29*8/100 -> 0 | P29: =(J29*75)+(L29*75/100)+(N29*75/100) -> 0
G30: =H30+I30+J30+K30+L30+M30+N30 -> 0 | H30: 0 | J30: =I30*16/100 -> 0 | L30: =K30*16/100 -> 0 | N30: =M30*8/100 -> 0 | P30: =(J30*75)+(L30*75/100)+(N30*75/100) -> 0
G31: =H31+I31+J31+K31+L31+M31+N31 -> 0 | H31: 0 | J31: =I31*16/100 -> 0 | L31: =K31*16/100 -> 0 | N31: =M31*8/100 -> 0 | P31: =(J31*75)+(L31*75/100)+(N31*75/100) -> 0
G32: =H32+I32+J32+K32+L32+M32+N32 -> 0 | H32: 0 | J32: =I32*16/100 -> 0 | L32: =K32*16/100 -> 0 | N32: =M32*8/100 -> 0 | P32: =(J32*75)+(L32*75/100)+(N32*75/100) -> 0
... G37: =H37+I37+J37+K37+L37+M37+N37 -> 0 | H37: 0 | J37: =I37*16/100 -> 0 | L37: =K37*16/100 -> 0 | N37: =M37*8/100 -> 0 | P37: =(J37*75)+(L37*75/100)+(N37*75/100) -> 0
A38: TOTALES | G38: =SUM(G20:G37) -> 19280 | H38: =SUM(H20:H37) -> 10000 | I38: =SUM(I20:I37) -> 8000 | J38: =SUM(J20:J37) -> 1280 | K38: =SUM(K20:K37) -> 0 | L38: =SUM(L20:L37) -> 0 | M38: =SUM(M20:M37) -> 0 | N38: =SUM(N20:N37) -> 0 | P38: =SUM(P20:P37) -> 96000
K42: Resumen Debitos Fiscales
K43: DÉBITOS FISCALES | O43: BASE IMPONIBLE | P43: DÉBITOS FISCALES
K44: Ventas internas no gravadas | L44: - | M44: - | O44: 0 | P44: 0
K45: Ventas internas gravadas por alícuota general | L45: - | M45: - | O45: 0 | P45: 0
K46: Ajustes a los débitos fiscales de periodos anteriores | M46: - | O46: 0 | P46: 0
K47: Total ventas y débitos fiscales para efectos de determinación | O47: 0 | P47: 0
K48: Total Débitos Fiscales | O48: =SUM(O44:O47) -> 0 | P48: =SUM(P44:P47) -> 0
K50: Resumen Creditos Fiscales
K51: CRÉDITOS FISCALES | O51: BASE IMPONIBLE | P51: CRÉDITO FISCAL
K52: Compras no gravadas y/o sin derecho a crédito fiscal | L52: - | O52: =H38 -> 10000 | P52: 0
K53: Importación gravadas por alícuota general | O53: 0 | P53: 0
K54: Compras internas gravadas por alícuota general | L54: - | M54: - | O54: =I38 -> 8000 | P54: =O54*16/100 -> 1280
K55: Compras internas gravadas por alícuota reducida | O55: 0 | P55: 0
K56: Total compras y créditos fiscales del periodo | L56: - | M56: - | O56: =SUM(O52:O55) -> 18000 | P56: =SUM(P52:P55) -> 1280
K57: Ajustes a los créditos fiscales de periodos anteriores | O57: 0 | P57: 0
K58: Total Créditos Fiscales | M58: - | O58: =O56-O57 -> 18000 | P58: =P56-P57 -> 1280
K60: AUTOLIQUIDACIÓN
...

Sheet Data
A1: Fecha de Operación | B1: Tipo de Documento | C1: Número de Documento | D1: Número de Control | E1: Nombre o Razón Social | F1: R.I.F. | G1: Total Compras | H1: Compras Exentas | I1: Base Imponible | J1: Alicuota (%) | K1: Credito Fiscales
A2: 46249 | B2: 1 | C2: 5 | D2: 5 | E2: Carlos Jose Rodrguez Colmenares | F2: V149899452 | G2: =H2+I2+K2+L2+M2+N2+O2 -> 19280 | H2: 10000 | I2: 8000 | J2: 16 | K2: =I2*16/100 -> 1280
A3: 46250 | B3: 1 | C3: 6 | D3: 6 | E3: Carlos Jose Rodrguez Colmenares | F3: V149899452 | G3: =H3+I3+K3+L3+M3+N3+O3 -> 19280 | H3: 10000 | I3: 8000 | J3: 16 | K3: =I3*16/100 -> 1280
A4: 46251 | B4: 1 | C4: 7 | D4: 7 | E4: Carlos Jose Rodrguez Colmenares | F4: V149899452 | G4: =H4+I4+K4+L4+M4+N4+O4 -> 19280 | H4: 10000 | I4: 8000 | J4: 16 | K4: =I4*16/100 -> 1280
