Workbook

Sheet Data
A1: Fecha de Operación | B1: Tipo de Documento | C1: Número de Documento | D1: Número de Control | E1: Número de Nota de Debito | F1: Número de Nota de Credito | G1: Número de factura Afectada | H1: Nombre o Razón Social | I1: R.I.F. | J1: Total Compras | K1: Compras Exentas | L1: Base Imponible | M1: Alicuota (%) | N1: Credito Fiscales
A2: 46147 | B2: 1 | C2: 10765 | D2: 00-009265 | E2: 0 | F2: 0 | G2: 0 | H2: DISTRIBUIDORA FREPARTES C.A. | I2: J313445320 | J2: =N2+L2+K2 -> 5798.376 | K2: 0 | L2: 4998.6 | M2: 16 | N2: =L2*16/100 -> 799.776
A3: 46147 | B3: 1 | C3: 19075 | D3: ZZP0018130 | E3: 0 | F3: 0 | G3: 0 | H3: PANADERIA, PASTELERIA Y DELICATESES AVINTES, C.A. | I3: J502708405 | J3: =N3+L3+K3 -> 8916.378 | K3: 4900.4 | L3: 3462.05 | M3: 16 | N3: =L3*16/100 -> 553.928
A4: 46150 | B4: 1 | C4: 35829 | D4: E000000230 | E4: 0 | F4: 0 | G4: 0 | H4: REPUESTOS YOGERES 06, C.A. | I4: J500732023 | J4: =N4+L4+K4 -> 9997.2048 | K4: 0 | L4: 8618.28 | M4: 16 | N4: =L4*16/100 -> 1378.9248
A5: 46150 | B5: 1 | C5: 51789 | D5: Z7C7038186 | E5: 0 | F5: 0 | G5: 0 | H5: PROMOTORA METROPOLITANA, DE RESTAURANTES 25, C.A. | I5: J311359036 | J5: =N5+L5+K5 -> 8997.482 | K5: 0 | L5: 7756.45 | M5: 16 | N5: =L5*16/100 -> 1241.032
A6: 46150 | B6: 1 | C6: 36085 | D6: Z7C7022224 | E6: 0 | F6: 0 | G6: 0 | H6: Grupo Canel, C.A. | I6: J409416860 | J6: =N6+L6+K6 -> 4528.3732 | K6: 0 | L6: 3903.77 | M6: 16 | N6: =L6*16/100 -> 624.6032
A7: 46150 | B7: 1 | C7: 84203 | D7: ZZP0006818 | E7: 0 | F7: 0 | G7: 0 | H7: MYKONOS GREEK FOOD, C.A. | I7: J504589616 | J7: =N7+L7+K7 -> 4998.6024 | K7: 0 | L7: 4309.14 | M7: 16 | N7: =L7*16/100 -> 689.4624
A8: 46152 | B8: 1 | C8: 73940 | D8: Z7C7000300 | E8: 0 | F8: 0 | G8: 0 | H8: INVERSIONES FLORENCIA 77, C.A. | I8: J317239199 | J8: =N8+L8+K8 -> 21217.572 | K8: 0 | L8: 18291.01 | M8: 16 | N8: =L8*16/100 -> 2926.5616
A9: 46152 | B9: 1 | C9: 5265 | D9: TIE2500154 | E9: 0 | F9: 0 | G9: 0 | H9: INVERSIONES FRAGANCE II 1999 C.A. | I9: J315404354 | J9: =N9+L9+K9 -> 28340.018 | K9: 0 | L9: 24431.05 | M9: 16 | N9: =L9*16/100 -> 3908.968
A10: 46153 | B10: 1 | C10: 2021 | D10: ZZN0003547 | E10: 0 | F10: 0 | G10: 0 | H10: TECNICA DE EMBRAGUES DOBLE INTOCABLES 2010, C.A. | I10: J298524545 | J10: =N10+L10+K10 -> 35399.998 | K10: 0 | L10: 30517.24 | M10: 16 | N10: =L10*16/100 -> 4882.7584
A11: 46153 | B11: 1 | C11: 3343 | D11: ZZP0013674 | E11: 0 | F11: 0 | G11: 0 | H11: Comercializadora TUA 2024, C.A. | I11: J505670743 | J11: =N11+L11+K11 -> 16334.56 | K11: 1296.39 | L11: 12963.94 | M11: 16 | N11: =L11*16/100 -> 2074.2304
A12: 46154 | B12: 1 | C12: 52555 | D12: Z7C7038186 | E12: 0 | F12: 0 | G12: 0 | H12: PROMOTORA METROPOLITANA, DE RESTAURANTES 25, C.A. | I12: J311359036 | J12: =N12+L12+K12 -> 7321.2124 | K12: 0 | L12: 6311.39 | M12: 16 | N12: =L12*16/100 -> 1009.8224
A13: 46154 | B13: 1 | C13: 959 | D13: ZZP0021188 | E13: 0 | F13: 0 | G13: 0 | H13: CONSORCIO IRB CCS, C.A. | I13: J507891054 | J13: =N13+L13+K13 -> 21350.009 | K13: 0 | L13: 18405.18 | M13: 16 | N13: =L13*16/100 -> 2944.8288
A14: 46154 | B14: 1 | C14: 10523 | D14: Z7C0022860 | E14: 0 | F14: 0 | G14: 0 | H14: FTL SBL CCS, C.A. | I14: J501690260 | J14: =N14+L14+K14 -> 54530.753 | K14: 0 | L14: 47009.27 | M14: 16 | N14: =L14*16/100 -> 7521.4832
A15: 46154 | B15: 1 | C15: 46952 | D15: ZZP0011912 | H15: MERAKI 222, C.A. | I15: J506138387 | J15: =N15+L15+K15 -> 8078.5416 | K15: 0 | L15: 6964.26 | M15: 16 | N15: =L15*16/100 -> 1114.2816
A16: 46155 | B16: 1 | C16: 5995 | D16: 5995 | E16: 0 | F16: 0 | G16: 0 | H16: MULTIREPUESTOS CHINA PARTS 1668, C.A | I16: J317555364 | J16: =N16+L16+K16 -> 54242.18 | K16: 0 | L16: 46760.5 | M16: 16 | N16: =L16*16/100 -> 7481.68
A17: 46155 | B17: 1 | C17: 2621 | D17: ZZL0002373 | E17: 0 | F17: 0 | G17: 0 | H17: SERVICIO TECNICO DE CAUCHOS ESTADIUM, C.A. | I17: J000622884 | J17: =N17+L17+K17 -> 20319.372 | K17: 0 | L17: 17516.7 | M17: 16 | N17: =L17*16/100 -> 2802.672
A18: 46155 | B18: 1 | C18: 2021 | D18: ZZN0003547 | E18: 0 | F18: 0 | G18: 0 | H18: TECNICA DE EMBRAGUES DOBLE INTOCABLES 2010, C.A. | I18: J298524545 | J18: =N18+L18+K18 -> 41499.998 | K18: 0 | L18: 35775.86 | M18: 16 | N18: =L18*16/100 -> 5724.1376
A19: 46156 | B19: 1 | C19: 5996 | D19: 5996 | E19: 0 | F19: 0 | G19: 0 | H19: MULTIREPUESTOS CHINA PARTS 1668, C.A | I19: J317555364 | J19: =N19+L19+K19 -> 26218.854 | K19: 0 | L19: 22602.46 | M19: 16 | N19: =L19*16/100 -> 3616.3936
A20: 46156 | B20: 1 | C20: 19657 | D20: ZZP0018130 | E20: 0 | F20: 0 | G20: 0 | H20: PANADERIA, PASTELERIA Y DELICATESES AVINTES, C.A. | I20: J502708405 | J20: =N20+L20+K20 -> 3371.2168 | K20: 766.17 | L20: 2245.73 | M20: 16 | N20: =L20*16/100 -> 359.3168
A21: 46159 | B21: 1 | C21: 53387 | D21: Z7C7038186 | E21: 0 | F21: 0 | G21: 0 | H21: PROMOTORA METROPOLITANA, DE RESTAURANTES 25, C.A. | I21: J311359036 | J21: =N21+L21+K21 -> 10100.224 | K21: 0 | L21: 8707.09 | M21: 16 | N21: =L21*16/100 -> 1393.1344
A22: 46160 | B22: 1 | C22: 6005 | D22: 6005 | E22: 0 | F22: 0 | G22: 0 | H22: MULTIREPUESTOS CHINA PARTS 1668, C.A | I22: J317555364 | J22: =N22+L22+K22 -> 31497.144 | K22: 0 | L22: 27152.71 | M22: 16 | N22: =L22*16/100 -> 4344.4336
A23: 46160 | B23: 1 | C23: 562 | D23: 00-001974 | E23: 0 | F23: 0 | G23: 0 | H23: REPUESTOS Y AUTOSERVICIO LA PAZ, C.A. | I23: J504638994 | J23: =N23+L23+K23 -> 114158.38 | K23: 0 | L23: 98412.4 | M23: 16 | N23: =L23*16/100 -> 15745.984
A24: 46162 | B24: 1 | C24: 3665 | D24: 1FC7002209 | E24: 0 | F24: 0 | G24: 0 | H24: DE TODO RESPUESTO AUTOMOTRIZ, C.A. | I24: J298830514 | J24: =N24+L24+K24 -> 420477.3 | K24: 0 | L24: 362480.43 | M24: 16 | N24: =L24*16/100 -> 57996.869
A25: 46164 | B25: 1 | C25: 6016 | D25: 6016 | E25: 0 | F25: 0 | G25: 0 | H25: MULTIREPUESTOS CHINA PARTS 1668, C.A | I25: J317555364 | J25: =N25+L25+K25 -> 14257.096 | K25: 0 | L25: 12290.6 | M25: 16 | N25: =L25*16/100 -> 1966.496
A26: 46165 | B26: 1 | C26: 20133 | D26: ZZP0018130 | E26: 0 | F26: 0 | G26: 0 | H26: PANADERIA, PASTELERIA Y DELICATESES AVINTES, C.A. | I26: J502708405 | J26: =N26+L26+K26 -> 10702.936 | K26: 7421.83 | L26: 2828.54 | M26: 16 | N26: =L26*16/100 -> 452.5664
A27: 46167 | B27: 1 | C27: 51645 | D27: Z7C7038186 | E27: 0 | F27: 0 | G27: 0 | H27: PROMOTORA METROPOLITANA, DE RESTAURANTES 25, C.A. | I27: J311359036 | J27: =N27+L27+K27 -> 17030.494 | K27: 0 | L27: 14681.46 | M27: 16 | N27: =L27*16/100 -> 2349.0336
A28: 46167 | B28: 1 | C28: 1 | D28: 00-0001 | E28: 0 | F28: 0 | G28: 0 | H28: GABRIAN JOELRODRIGUEZ SALCEDO | I28: V238076869 | J28: =N28+L28+K28 -> 274654.2 | K28: 0 | L28: 236770.86 | M28: 16 | N28: =L28*16/100 -> 37883.338
A29: 46168 | B29: 1 | C29: 158 | D29: 00-000158 | H29: JORGE E. GONZALES SILVA | I29: V056081042 | J29: =N29+L29+K29 -> 195273.88 | K29: 0 | L29: 168339.55 | M29: 16 | N29: =L29*16/100 -> 26934.328
A30: 46168 | B30: 1 | C30: 446 | D30: 00-050775 | H30: AGRORUEDAS CHAKAO, C.A. | I30: J410230940 | J30: =N30+L30+K30 -> 65092.031 | K30: 0 | L30: 56113.82 | M30: 16 | N30: =L30*16/100 -> 8978.2112
A31: 46168 | B31: 1 | C31: 54889 | D31: Z7C7038186 | H31: PROMOTORA METROPOLITANA, DE RESTAURANTES 25, C.A. | I31: J311359036 | J31: =N31+L31+K31 -> 9904.5324 | K31: 0 | L31: 8538.39 | M31: 16 | N31: =L31*16/100 -> 1366.1424
A32: 46168 | B32: 1 | C32: 0 | D32: 0 | E32: 0 | F32: 331 | G32: 446 | H32: AGRORUEDAS CHAKAO, C.A. | I32: J410230940 | J32: =N32+L32+K32 -> -4283.0796 | K32: 0 | L32: -3692.31 | M32: 16 | N32: =L32*16/100 -> -590.7696
A33: 46169 | B33: 1 | C33: 6024 | D33: 6024 | H33: MULTIREPUESTOS CHINA PARTS 1668, C.A | I33: J317555364 | J33: =N33+L33+K33 -> 16055.154 | K33: 0 | L33: 13840.65 | M33: 16 | N33: =L33*16/100 -> 2214.504
A34: 46169 | B34: 1 | C34: 2284 | D34: 2284 | E34: 0 | F34: 0 | G34: 0 | H34: REIKO IMPORT, C.A. | I34: J298420065 | J34: =N34+L34+K34 -> 280300.08 | K34: 0 | L34: 241638 | M34: 16 | N34: =L34*16/100 -> 38662.08
A35: 46169 | B35: 1 | C35: 20315 | D35: ZZP0018130 | E35: 0 | F35: 0 | G35: 0 | H35: PANADERIA, PASTELERIA Y DELICATESES AVINTES, C.A. | I35: J502708405 | J35: =N35+L35+K35 -> 4957.5732 | K35: 3229.44 | L35: 1489.77 | M35: 16 | N35: =L35*16/100 -> 238.3632
A36: 46171 | B36: 1 | C36: 89388 | D36: Z7C0028758 | E36: 0 | F36: 0 | G36: 0 | H36: Pasta Morandi, C.A. | I36: J001598693 | J36: =N36+L36+K36 -> 13185.105 | K36: 0 | L36: 11366.47 | M36: 16 | N36: =L36*16/100 -> 1818.6352
A37: 46172 | B37: 1 | C37: 83903 | D37: Z7C0028754 | E37: 0 | F37: 0 | G37: 0 | H37: INVERSIONES RG 11-32 C.A. | I37: J308562157 | J37: =N37+L37+K37 -> 14082.249 | K37: 0 | L37: 12139.87 | M37: 16 | N37: =L37*16/100 -> 1942.3792
A38: 46172 | B38: 1 | C38: 10692 | D38: Z7C0022860 | E38: 0 | F38: 0 | G38: 0 | H38: FTL SBL CCS, C.A. | I38: J501690260 | J38: =N38+L38+K38 -> 59877.959 | K38: 0 | L38: 51618.93 | M38: 16 | N38: =L38*16/100 -> 8259.0288
A39: 46173 | B39: 1 | C39: 55689 | D39: Z7C7038186 | E39: 0 | F39: 0 | G39: 0 | H39: PROMOTORA METROPOLITANA, DE RESTAURANTES 25, C.A. | I39: J311359036 | J39: =N39+L39+K39 -> 13306.082 | K39: 0 | L39: 11470.76 | M39: 16 | N39: =L39*16/100 -> 1835.3216
A40: 46168 | B40: 1 | C40: 7 | D40: 00-000007 | E40: 0 | F40: 0 | G40: 0 | H40: MULTISERVICIOS C.J.P.J.D 2025, C.A. | I40: J507273164 | J40: =N40+L40+K40 -> 96050.32 | K40: 0 | L40: 82802 | M40: 16 | N40: =L40*16/100 -> 13248.32
...

Sheet Libro de Compras
A2: Razon Social: | B2: KING DRIVER, C.A.
A3: R.I.F: | B3: J507757188
A6: Razon Social: | B6: KING DRIVER, C.A.
A7: R.I.F: | B7: J507757188
A8: Direccion | B8: AV. JOSE ANTONIO PAEZ EDIF RESIDENCIAS 2000 RESIDENCIAS CECILIA PISO PH APT 43 URB EL PARAISO CARACAS DISTRITO CAPITAL ZONA POSTAL 1020.
A9: Libro de Compra
A10: Periodo: | B10: 202605
A11: Fecha | B11: 46173
L15: Compras Nacionales (16%) | N15: Compras Importacion (16%) | P15: Alicuota Reducida (8%) | R15: Retencion 75%
A16: Fecha de Operación | B16: Tipo de Documento | C16: Número de Documento | D16: Número de Control | E16: Número de Nota de Debito | F16: Número de Nota de Credito | G16: Número de factura Afectada | H16: Nombre o Razón Social | I16: R.I.F. | J16: Total Compras | K16: Compras Exentas | L16: Base Imponible | M16: Credito Fiscales | N16: Base Imponible | O16: Credito Fiscales | P16: Base Imponible | Q16: Credito Fiscales | R16: Nº Documento | S16: 0.75
A17: =Data!A2 -> 46147 | B17: =Data!B2 -> 1 | C17: =Data!C2 -> 10765 | D17: =Data!D2 -> 00-009265 | E17: =Data!E2 -> 0 | F17: =Data!F2 -> 0 | G17: =Data!G2 -> 0 | H17: =Data!H2 -> DISTRIBUIDORA FREPARTES C.A. | I17: =Data!I2 -> J313445320 | J17: =K17+L17+M17+N17+O17+P17+Q17 -> 5798.376 | K17: =Data!K2 -> 0 | L17: =Data!L2 -> 4998.6 | M17: =L17*16/100 -> 799.776 | N17: 0 | O17: =N17*16/100 -> 0 | P17: 0 | Q17: =P17*8/100 -> 0 | S17: 0
A18: =Data!A3 -> 46147 | B18: =Data!B3 -> 1 | C18: =Data!C3 -> 19075 | D18: =Data!D3 -> ZZP0018130 | E18: =Data!E3 -> 0 | F18: =Data!F3 -> 0 | G18: =Data!G3 -> 0 | H18: =Data!H3 -> PANADERIA, PASTELERIA Y DELICATESES AVINTES, C.A. | I18: =Data!I3 -> J502708405 | J18: =K18+L18+M18+N18+O18+P18+Q18 -> 8916.378 | K18: =Data!K3 -> 4900.4 | L18: =Data!L3 -> 3462.05 | M18: =L18*16/100 -> 553.928 | N18: 0 | O18: =N18*16/100 -> 0 | P18: 0 | Q18: =P18*8/100 -> 0 | S18: 0
A19: =Data!A4 -> 46150 | B19: =Data!B4 -> 1 | C19: =Data!C4 -> 35829 | D19: =Data!D4 -> E000000230 | E19: =Data!E4 -> 0 | F19: =Data!F4 -> 0 | G19: =Data!G4 -> 0 | H19: =Data!H4 -> REPUESTOS YOGERES 06, C.A. | I19: =Data!I4 -> J500732023 | J19: =K19+L19+M19+N19+O19+P19+Q19 -> 9997.2048 | K19: =Data!K4 -> 0 | L19: =Data!L4 -> 8618.28 | M19: =L19*16/100 -> 1378.9248 | N19: 0 | O19: =N19*16/100 -> 0 | P19: 0 | Q19: =P19*8/100 -> 0 | S19: 0
A20: =Data!A5 -> 46150 | B20: =Data!B5 -> 1 | C20: =Data!C5 -> 51789 | D20: =Data!D5 -> Z7C7038186 | E20: =Data!E5 -> 0 | F20: =Data!F5 -> 0 | G20: =Data!G5 -> 0 | H20: =Data!H5 -> PROMOTORA METROPOLITANA, DE RESTAURANTES 25, C.A. | I20: =Data!I5 -> J311359036 | J20: =K20+L20+M20+N20+O20+P20+Q20 -> 8997.482 | K20: =Data!K5 -> 0 | L20: =Data!L5 -> 7756.45 | M20: =L20*16/100 -> 1241.032 | N20: 0 | O20: =N20*16/100 -> 0 | P20: 0 | Q20: =P20*8/100 -> 0 | S20: 0
A21: =Data!A6 -> 46150 | B21: =Data!B6 -> 1 | C21: =Data!C6 -> 36085 | D21: =Data!D6 -> Z7C7022224 | E21: =Data!E6 -> 0 | F21: =Data!F6 -> 0 | G21: =Data!G6 -> 0 | H21: =Data!H6 -> Grupo Canel, C.A. | I21: =Data!I6 -> J409416860 | J21: =K21+L21+M21+N21+O21+P21+Q21 -> 4528.3732 | K21: =Data!K6 -> 0 | L21: =Data!L6 -> 3903.77 | M21: =L21*16/100 -> 624.6032 | N21: 0 | O21: =N21*16/100 -> 0 | P21: 0 | Q21: =P21*8/100 -> 0 | S21: 0
A22: =Data!A7 -> 46150 | B22: =Data!B7 -> 1 | C22: =Data!C7 -> 84203 | D22: =Data!D7 -> ZZP0006818 | E22: =Data!E7 -> 0 | F22: =Data!F7 -> 0 | G22: =Data!G7 -> 0 | H22: =Data!H7 -> MYKONOS GREEK FOOD, C.A. | I22: =Data!I7 -> J504589616 | J22: =K22+L22+M22+N22+O22+P22+Q22 -> 4998.6024 | K22: =Data!K7 -> 0 | L22: =Data!L7 -> 4309.14 | M22: =L22*16/100 -> 689.4624 | N22: 0 | O22: =N22*16/100 -> 0 | P22: 0 | Q22: =P22*8/100 -> 0 | S22: 0
A23: =Data!A8 -> 46152 | B23: =Data!B8 -> 1 | C23: =Data!C8 -> 73940 | D23: =Data!D8 -> Z7C7000300 | E23: =Data!E8 -> 0 | F23: =Data!F8 -> 0 | G23: =Data!G8 -> 0 | H23: =Data!H8 -> INVERSIONES FLORENCIA 77, C.A. | I23: =Data!I8 -> J317239199 | J23: =K23+L23+M23+N23+O23+P23+Q23 -> 21217.572 | K23: =Data!K8 -> 0 | L23: =Data!L8 -> 18291.01 | M23: =L23*16/100 -> 2926.5616 | N23: 0 | O23: =N23*16/100 -> 0 | P23: 0 | Q23: =P23*8/100 -> 0 | S23: 0
A24: =Data!A9 -> 46152 | B24: =Data!B9 -> 1 | C24: =Data!C9 -> 5265 | D24: =Data!D9 -> TIE2500154 | E24: =Data!E9 -> 0 | F24: =Data!F9 -> 0 | G24: =Data!G9 -> 0 | H24: =Data!H9 -> INVERSIONES FRAGANCE II 1999 C.A. | I24: =Data!I9 -> J315404354 | J24: =K24+L24+M24+N24+O24+P24+Q24 -> 28340.018 | K24: =Data!K9 -> 0 | L24: =Data!L9 -> 24431.05 | M24: =L24*16/100 -> 3908.968 | N24: 0 | O24: =N24*16/100 -> 0 | P24: 0 | Q24: =P24*8/100 -> 0 | S24: 0
A25: =Data!A10 -> 46153 | B25: =Data!B10 -> 1 | C25: =Data!C10 -> 2021 | D25: =Data!D10 -> ZZN0003547 | E25: =Data!E10 -> 0 | F25: =Data!F10 -> 0 | G25: =Data!G10 -> 0 | H25: =Data!H10 -> TECNICA DE EMBRAGUES DOBLE INTOCABLES 2010, C.A. | I25: =Data!I10 -> J298524545 | J25: =K25+L25+M25+N25+O25+P25+Q25 -> 35399.998 | K25: =Data!K10 -> 0 | L25: =Data!L10 -> 30517.24 | M25: =L25*16/100 -> 4882.7584 | N25: 0 | O25: =N25*16/100 -> 0 | P25: 0 | Q25: =P25*8/100 -> 0 | S25: 0
A26: =Data!A11 -> 46153 | B26: =Data!B11 -> 1 | C26: =Data!C11 -> 3343 | D26: =Data!D11 -> ZZP0013674 | E26: =Data!E11 -> 0 | F26: =Data!F11 -> 0 | G26: =Data!G11 -> 0 | H26: =Data!H11 -> Comercializadora TUA 2024, C.A. | I26: =Data!I11 -> J505670743 | J26: =K26+L26+M26+N26+O26+P26+Q26 -> 16334.56 | K26: =Data!K11 -> 1296.39 | L26: =Data!L11 -> 12963.94 | M26: =L26*16/100 -> 2074.2304 | N26: 0 | O26: =N26*16/100 -> 0 | P26: 0 | Q26: =P26*8/100 -> 0 | S26: 0
A27: =Data!A12 -> 46154 | B27: =Data!B12 -> 1 | C27: =Data!C12 -> 52555 | D27: =Data!D12 -> Z7C7038186 | E27: =Data!E12 -> 0 | F27: =Data!F12 -> 0 | G27: =Data!G12 -> 0 | H27: =Data!H12 -> PROMOTORA METROPOLITANA, DE RESTAURANTES 25, C.A. | I27: =Data!I12 -> J311359036 | J27: =K27+L27+M27+N27+O27+P27+Q27 -> 7321.2124 | K27: =Data!K12 -> 0 | L27: =Data!L12 -> 6311.39 | M27: =L27*16/100 -> 1009.8224 | N27: 0 | O27: =N27*16/100 -> 0 | P27: 0 | Q27: =P27*8/100 -> 0 | S27: 0
A28: =Data!A13 -> 46154 | B28: =Data!B13 -> 1 | C28: =Data!C13 -> 959 | D28: =Data!D13 -> ZZP0021188 | E28: =Data!E13 -> 0 | F28: =Data!F13 -> 0 | G28: =Data!G13 -> 0 | H28: =Data!H13 -> CONSORCIO IRB CCS, C.A. | I28: =Data!I13 -> J507891054 | J28: =K28+L28+M28+N28+O28+P28+Q28 -> 21350.009 | K28: =Data!K13 -> 0 | L28: =Data!L13 -> 18405.18 | M28: =L28*16/100 -> 2944.8288 | N28: 0 | O28: =N28*16/100 -> 0 | P28: 0 | Q28: =P28*8/100 -> 0 | S28: 0
... A57: =Data!A42 -> 46170 | B57: =Data!B42 -> 1 | C57: =Data!C42 -> 3718 | D57: =Data!D42 -> 1FC7002209 | E57: =Data!E42 -> 0 | F57: =Data!F42 -> 0 | G57: =Data!G42 -> 0 | H57: =Data!H42 -> DE TODO RESPUESTO AUTOMOTRIZ, C.A. | I57: =Data!I42 -> J298830514 | J57: =K57+L57+M57+N57+O57+P57+Q57 -> 27226.789 | K57: =Data!K42 -> 0 | L57: =Data!L42 -> 23471.37 | M57: =L57*16/100 -> 3755.4192 | N57: 0 | O57: =N57*16/100 -> 0 | P57: 0 | Q57: =P57*8/100 -> 0 | S57: 0
A58: TOTALES | J58: =SUM(J17:J57) -> 2448566.4 | K58: =SUM(K17:K57) -> 17614.23 | L58: =SUM(L17:L57) -> 2095648.4 | M58: =SUM(M17:M57) -> 335303.75 | N58: =SUM(N17:N52) -> 0 | O58: =SUM(O17:O52) -> 0 | P58: =SUM(P17:P52) -> 0 | Q58: =SUM(Q17:Q52) -> 0 | S58: =SUM(S17:S52) -> 0
N62: Resumen Debitos Fiscales
N63: DÉBITOS FISCALES | R63: BASE IMPONIBLE | S63: DÉBITOS FISCALES
N64: Ventas internas no gravadas | O64: - | P64: - | R64: 2961045.9 | S64: 0
N65: Ventas internas gravadas por alícuota general | O65: - | P65: - | R65: 0 | S65: 0
N66: Ajustes a los débitos fiscales de periodos anteriores | P66: - | R66: 0 | S66: 0
N67: Total ventas y débitos fiscales para efectos de determinación | R67: =SUM(R64:R66) -> 2961045.9 | S67: 0
N68: Total Débitos Fiscales | R68: 0 | S68: =SUM(S64:S67) -> 0
N70: Resumen Creditos Fiscales
N71: CRÉDITOS FISCALES | R71: BASE IMPONIBLE | S71: CRÉDITO FISCAL
N72: Compras no gravadas y/o sin derecho a crédito fiscal | O72: - | R72: =K58 -> 17614.23 | S72: 0
N73: Importación gravadas por alícuota general | R73: 0 | S73: 0
N74: Compras internas gravadas por alícuota general | O74: - | P74: - | R74: =L58 -> 2095648.4 | S74: =R74*16/100 -> 335303.75
N75: Compras internas gravadas por alícuota reducida | R75: 0 | S75: 0
N76: Total compras y créditos fiscales del periodo | O76: - | P76: - | R76: =SUM(R72:R75) -> 2113262.7 | S76: =SUM(S72:S75) -> 335303.75
N77: Ajustes a los créditos fiscales de periodos anteriores | R77: 0 | S77: 0
N78: Total Créditos Fiscales | P78: - | R78: =R76-R77 -> 2113262.7 | S78: =S76-S77 -> 335303.75
...
